Workbook

Sheet SVNCKH2025_2026
A1: TT | B1: Tên đề tài | C1: Detai_name | D1: SV/nhóm SV thực hiện | E1: Mã số sinh viên | F1: Lớp | G1: Người hướng dẫn | H1: Ghi chú | I1: donvi_cu | J1: donvi_name | K1: donvi_ma | L1: ngay_thang | M1: năm
A2: 1 | B2: Phương pháp chỉnh hóa kiểu Tikhonov cho bài toán xác định nguồn trong phương trình đạo hàm riêng | C2: Phương pháp chỉnh hóa kiểu Tikhonov cho bài toán xác định nguồn trong phương trình đạo hàm riêng | D2: Trần Thành Lợi | E2: 3110124037 | F2: 24ST1 | G2: PGS.TS. Phạm Quý Mười | I2: KHOA TOÁN (14 đề tài) | J2: =IFS( ISNUMBER(SEARCH("toán",I2)),"Khoa Toán - Tin, Trường ĐHSP", ISNUMBER(SEARCH("tin",I2)),"Khoa Toán - Tin, Trường ĐHSP", ISNUMBER(SEARCH("lý",I2)),"Khoa Lý - Hóa, Trường ĐHSP", ISNUMBER(SEARCH("hóa",I2)),"Khoa Lý - Hóa, Trường ĐHSP", ISNUMBER(SEARCH("ngữ văn",I2)),"Khoa Ngữ văn - Truyền thông, Trường ĐHSP", ISNUMBER(SEARCH("sử",I2)),"Khoa Sử - Địa - Chính trị, Trường ĐHSP", ISNUMBER(SEARCH("địa",I2)),"Khoa Sử - Địa - Chính trị, Trường ĐHSP", ISNUMBER(SEARCH("chính trị",I2)),"Khoa Sử - Địa - Chính trị, Trường ĐHSP", ISNUMBER(SEARCH("sinh",I2)),"Khoa Sinh - Nông nghiệp - Môi trường, Trường ĐHSP", ISNUMBER(SEARCH("tiểu học",I2)),"Khoa Giáo dục Tiểu học - Mầm non, Trường ĐHSP", ISNUMBER(SEARCH("mầm non",I2)),"Khoa Giáo dục Tiểu học - Mầm non, Trường ĐHSP", ISNUMBER(SEARCH("nghệ thuật",I2)),"Khoa Giáo dục Nghệ thuật - Thể chất, Trường ĐHSP", ISNUMBER(SEARCH("tâm lý",I2)),"Khoa Tâm lý - Giáo dục - Công tác Xã hội, Trường ĐHSP" ) -> #NAME? | K2: =VLOOKUP(J2,'Bảng Đơn vị'!$A$2:$B$10,2,1) -> #NAME? | L2: 45667 | M2: 2025
A3: 2 | C3: =IF(B3<>"",B3,C2) -> Phương pháp chỉnh hóa kiểu Tikhonov cho bài toán xác định nguồn trong phương trình đạo hàm riêng | D3: Trịnh Khải Hoàn | E3: 3110124020 | F3: 24ST2 | I3: KHOA TOÁN (14 đề tài) | J3: =IFS( ISNUMBER(SEARCH("toán",I3)),"Khoa Toán - Tin, Trường ĐHSP", ISNUMBER(SEARCH("tin",I3)),"Khoa Toán - Tin, Trường ĐHSP", ISNUMBER(SEARCH("lý",I3)),"Khoa Lý - Hóa, Trường ĐHSP", ISNUMBER(SEARCH("hóa",I3)),"Khoa Lý - Hóa, Trường ĐHSP", ISNUMBER(SEARCH("ngữ văn",I3)),"Khoa Ngữ văn - Truyền thông, Trường ĐHSP", ISNUMBER(SEARCH("sử",I3)),"Khoa Sử - Địa - Chính trị, Trường ĐHSP", ISNUMBER(SEARCH("địa",I3)),"Khoa Sử - Địa - Chính trị, Trường ĐHSP", ISNUMBER(SEARCH("chính trị",I3)),"Khoa Sử - Địa - Chính trị, Trường ĐHSP", ISNUMBER(SEARCH("sinh",I3)),"Khoa Sinh - Nông nghiệp - Môi trường, Trường ĐHSP", ISNUMBER(SEARCH("tiểu học",I3)),"Khoa Giáo dục Tiểu học - Mầm non, Trường ĐHSP", ISNUMBER(SEARCH("mầm non",I3)),"Khoa Giáo dục Tiểu học - Mầm non, Trường ĐHSP", ISNUMBER(SEARCH("nghệ thuật",I3)),"Khoa Giáo dục Nghệ thuật - Thể chất, Trường ĐHSP", ISNUMBER(SEARCH("tâm lý",I3)),"Khoa Tâm lý - Giáo dục - Công tác Xã hội, Trường ĐHSP" ) -> #NAME? | K3: =VLOOKUP(J3,'Bảng Đơn vị'!$A$2:$B$10,2,1) -> #NAME? | L3: 45668 | M3: 2025
A4: 3 | C4: =IF(B4<>"",B4,C3) -> Phương pháp chỉnh hóa kiểu Tikhonov cho bài toán xác định nguồn trong phương trình đạo hàm riêng | D4: Nguyễn Thị Thanh Châu | E4: 3110124007 | F4: 24ST1 | I4: KHOA TOÁN (14 đề tài) | J4: =IFS( ISNUMBER(SEARCH("toán",I4)),"Khoa Toán - Tin, Trường ĐHSP", ISNUMBER(SEARCH("tin",I4)),"Khoa Toán - Tin, Trường ĐHSP", ISNUMBER(SEARCH("lý",I4)),"Khoa Lý - Hóa, Trường ĐHSP", ISNUMBER(SEARCH("hóa",I4)),"Khoa Lý - Hóa, Trường ĐHSP", ISNUMBER(SEARCH("ngữ văn",I4)),"Khoa Ngữ văn - Truyền thông, Trường ĐHSP", ISNUMBER(SEARCH("sử",I4)),"Khoa Sử - Địa - Chính trị, Trường ĐHSP", ISNUMBER(SEARCH("địa",I4)),"Khoa Sử - Địa - Chính trị, Trường ĐHSP", ISNUMBER(SEARCH("chính trị",I4)),"Khoa Sử - Địa - Chính trị, Trường ĐHSP", ISNUMBER(SEARCH("sinh",I4)),"Khoa Sinh - Nông nghiệp - Môi trường, Trường ĐHSP", ISNUMBER(SEARCH("tiểu học",I4)),"Khoa Giáo dục Tiểu học - Mầm non, Trường ĐHSP", ISNUMBER(SEARCH("mầm non",I4)),"Khoa Giáo dục Tiểu học - Mầm non, Trường ĐHSP", ISNUMBER(SEARCH("nghệ thuật",I4)),"Khoa Giáo dục Nghệ thuật - Thể chất, Trường ĐHSP", ISNUMBER(SEARCH("tâm lý",I4)),"Khoa Tâm lý - Giáo dục - Công tác Xã hội, Trường ĐHSP" ) -> #NAME? | K4: =VLOOKUP(J4,'Bảng Đơn vị'!$A$2:$B$10,2,1) -> #NAME? | L4: 45669 | M4: 2025
A5: 4 | C5: =IF(B5<>"",B5,C4) -> Phương pháp chỉnh hóa kiểu Tikhonov cho bài toán xác định nguồn trong phương trình đạo hàm riêng | D5: Đinh Thành Tuân | E5: 3110121144 | F5: 21ST2 | I5: KHOA TOÁN (14 đề tài) | J5: =IFS( ISNUMBER(SEARCH("toán",I5)),"Khoa Toán - Tin, Trường ĐHSP", ISNUMBER(SEARCH("tin",I5)),"Khoa Toán - Tin, Trường ĐHSP", ISNUMBER(SEARCH("lý",I5)),"Khoa Lý - Hóa, Trường ĐHSP", ISNUMBER(SEARCH("hóa",I5)),"Khoa Lý - Hóa, Trường ĐHSP", ISNUMBER(SEARCH("ngữ văn",I5)),"Khoa Ngữ văn - Truyền thông, Trường ĐHSP", ISNUMBER(SEARCH("sử",I5)),"Khoa Sử - Địa - Chính trị, Trường ĐHSP", ISNUMBER(SEARCH("địa",I5)),"Khoa Sử - Địa - Chính trị, Trường ĐHSP", ISNUMBER(SEARCH("chính trị",I5)),"Khoa Sử - Địa - Chính trị, Trường ĐHSP", ISNUMBER(SEARCH("sinh",I5)),"Khoa Sinh - Nông nghiệp - Môi trường, Trường ĐHSP", ISNUMBER(SEARCH("tiểu học",I5)),"Khoa Giáo dục Tiểu học - Mầm non, Trường ĐHSP", ISNUMBER(SEARCH("mầm non",I5)),"Khoa Giáo dục Tiểu học - Mầm non, Trường ĐHSP", ISNUMBER(SEARCH("nghệ thuật",I5)),"Khoa Giáo dục Nghệ thuật - Thể chất, Trường ĐHSP", ISNUMBER(SEARCH("tâm lý",I5)),"Khoa Tâm lý - Giáo dục - Công tác Xã hội, Trường ĐHSP" ) -> #NAME? | K5: =VLOOKUP(J5,'Bảng Đơn vị'!$A$2:$B$10,2,1) -> #NAME? | L5: 45670 | M5: 2025
A6: 5 | C6: =IF(B6<>"",B6,C5) -> Phương pháp chỉnh hóa kiểu Tikhonov cho bài toán xác định nguồn trong phương trình đạo hàm riêng | D6: Đỗ Thị Ly Na | E6: 3110124044 | F6: 24ST2 | I6: KHOA TOÁN (14 đề tài) | J6: =IFS( ISNUMBER(SEARCH("toán",I6)),"Khoa Toán - Tin, Trường ĐHSP", ISNUMBER(SEARCH("tin",I6)),"Khoa Toán - Tin, Trường ĐHSP", ISNUMBER(SEARCH("lý",I6)),"Khoa Lý - Hóa, Trường ĐHSP", ISNUMBER(SEARCH("hóa",I6)),"Khoa Lý - Hóa, Trường ĐHSP", ISNUMBER(SEARCH("ngữ văn",I6)),"Khoa Ngữ văn - Truyền thông, Trường ĐHSP", ISNUMBER(SEARCH("sử",I6)),"Khoa Sử - Địa - Chính trị, Trường ĐHSP", ISNUMBER(SEARCH("địa",I6)),"Khoa Sử - Địa - Chính trị, Trường ĐHSP", ISNUMBER(SEARCH("chính trị",I6)),"Khoa Sử - Địa - Chính trị, Trường ĐHSP", ISNUMBER(SEARCH("sinh",I6)),"Khoa Sinh - Nông nghiệp - Môi trường, Trường ĐHSP", ISNUMBER(SEARCH("tiểu học",I6)),"Khoa Giáo dục Tiểu học - Mầm non, Trường ĐHSP", ISNUMBER(SEARCH("mầm non",I6)),"Khoa Giáo dục Tiểu học - Mầm non, Trường ĐHSP", ISNUMBER(SEARCH("nghệ thuật",I6)),"Khoa Giáo dục Nghệ thuật - Thể chất, Trường ĐHSP", ISNUMBER(SEARCH("tâm lý",I6)),"Khoa Tâm lý - Giáo dục - Công tác Xã hội, Trường ĐHSP" ) -> #NAME? | K6: =VLOOKUP(J6,'Bảng Đơn vị'!$A$2:$B$10,2,1) -> #NAME? | L6: 45671 | M6: 2025
A7: 6 | B7: Đạo hàm Newton cho hàm một biến số thực và ứng dụng | C7: =IF(B7<>"",B7,C6) -> Đạo hàm Newton cho hàm một biến số thực và ứng dụng | D7: Nguyễn Ngô Yến Nhi | E7: 3110124050 | F7: 24ST2 | G7: PGS.TS. Phạm Quý Mười | I7: KHOA TOÁN (14 đề tài) | J7: =IFS( ISNUMBER(SEARCH("toán",I7)),"Khoa Toán - Tin, Trường ĐHSP", ISNUMBER(SEARCH("tin",I7)),"Khoa Toán - Tin, Trường ĐHSP", ISNUMBER(SEARCH("lý",I7)),"Khoa Lý - Hóa, Trường ĐHSP", ISNUMBER(SEARCH("hóa",I7)),"Khoa Lý - Hóa, Trường ĐHSP", ISNUMBER(SEARCH("ngữ văn",I7)),"Khoa Ngữ văn - Truyền thông, Trường ĐHSP", ISNUMBER(SEARCH("sử",I7)),"Khoa Sử - Địa - Chính trị, Trường ĐHSP", ISNUMBER(SEARCH("địa",I7)),"Khoa Sử - Địa - Chính trị, Trường ĐHSP", ISNUMBER(SEARCH("chính trị",I7)),"Khoa Sử - Địa - Chính trị, Trường ĐHSP", ISNUMBER(SEARCH("sinh",I7)),"Khoa Sinh - Nông nghiệp - Môi trường, Trường ĐHSP", ISNUMBER(SEARCH("tiểu học",I7)),"Khoa Giáo dục Tiểu học - Mầm non, Trường ĐHSP", ISNUMBER(SEARCH("mầm non",I7)),"Khoa Giáo dục Tiểu học - Mầm non, Trường ĐHSP", ISNUMBER(SEARCH("nghệ thuật",I7)),"Khoa Giáo dục Nghệ thuật - Thể chất, Trường ĐHSP", ISNUMBER(SEARCH("tâm lý",I7)),"Khoa Tâm lý - Giáo dục - Công tác Xã hội, Trường ĐHSP" ) -> #NAME? | K7: =VLOOKUP(J7,'Bảng Đơn vị'!$A$2:$B$10,2,1) -> #NAME? | L7: 45672 | M7: 2025
A8: 7 | C8: =IF(B8<>"",B8,C7) -> Đạo hàm Newton cho hàm một biến số thực và ứng dụng | D8: Nguyễn Lam Thi | E8: 3110124065 | I8: KHOA TOÁN (14 đề tài) | J8: =IFS( ISNUMBER(SEARCH("toán",I8)),"Khoa Toán - Tin, Trường ĐHSP", ISNUMBER(SEARCH("tin",I8)),"Khoa Toán - Tin, Trường ĐHSP", ISNUMBER(SEARCH("lý",I8)),"Khoa Lý - Hóa, Trường ĐHSP", ISNUMBER(SEARCH("hóa",I8)),"Khoa Lý - Hóa, Trường ĐHSP", ISNUMBER(SEARCH("ngữ văn",I8)),"Khoa Ngữ văn - Truyền thông, Trường ĐHSP", ISNUMBER(SEARCH("sử",I8)),"Khoa Sử - Địa - Chính trị, Trường ĐHSP", ISNUMBER(SEARCH("địa",I8)),"Khoa Sử - Địa - Chính trị, Trường ĐHSP", ISNUMBER(SEARCH("chính trị",I8)),"Khoa Sử - Địa - Chính trị, Trường ĐHSP", ISNUMBER(SEARCH("sinh",I8)),"Khoa Sinh - Nông nghiệp - Môi trường, Trường ĐHSP", ISNUMBER(SEARCH("tiểu học",I8)),"Khoa Giáo dục Tiểu học - Mầm non, Trường ĐHSP", ISNUMBER(SEARCH("mầm non",I8)),"Khoa Giáo dục Tiểu học - Mầm non, Trường ĐHSP", ISNUMBER(SEARCH("nghệ thuật",I8)),"Khoa Giáo dục Nghệ thuật - Thể chất, Trường ĐHSP", ISNUMBER(SEARCH("tâm lý",I8)),"Khoa Tâm lý - Giáo dục - Công tác Xã hội, Trường ĐHSP" ) -> #NAME? | K8: =VLOOKUP(J8,'Bảng Đơn vị'!$A$2:$B$10,2,1) -> #NAME? | L8: 45673 | M8: 2025
A9: 8 | C9: =IF(B9<>"",B9,C8) -> Đạo hàm Newton cho hàm một biến số thực và ứng dụng | D9: Phan Thanh Tùng | E9: 3110124090 | I9: KHOA TOÁN (14 đề tài) | J9: =IFS( ISNUMBER(SEARCH("toán",I9)),"Khoa Toán - Tin, Trường ĐHSP", ISNUMBER(SEARCH("tin",I9)),"Khoa Toán - Tin, Trường ĐHSP", ISNUMBER(SEARCH("lý",I9)),"Khoa Lý - Hóa, Trường ĐHSP", ISNUMBER(SEARCH("hóa",I9)),"Khoa Lý - Hóa, Trường ĐHSP", ISNUMBER(SEARCH("ngữ văn",I9)),"Khoa Ngữ văn - Truyền thông, Trường ĐHSP", ISNUMBER(SEARCH("sử",I9)),"Khoa Sử - Địa - Chính trị, Trường ĐHSP", ISNUMBER(SEARCH("địa",I9)),"Khoa Sử - Địa - Chính trị, Trường ĐHSP", ISNUMBER(SEARCH("chính trị",I9)),"Khoa Sử - Địa - Chính trị, Trường ĐHSP", ISNUMBER(SEARCH("sinh",I9)),"Khoa Sinh - Nông nghiệp - Môi trường, Trường ĐHSP", ISNUMBER(SEARCH("tiểu học",I9)),"Khoa Giáo dục Tiểu học - Mầm non, Trường ĐHSP", ISNUMBER(SEARCH("mầm non",I9)),"Khoa Giáo dục Tiểu học - Mầm non, Trường ĐHSP", ISNUMBER(SEARCH("nghệ thuật",I9)),"Khoa Giáo dục Nghệ thuật - Thể chất, Trường ĐHSP", ISNUMBER(SEARCH("tâm lý",I9)),"Khoa Tâm lý - Giáo dục - Công tác Xã hội, Trường ĐHSP" ) -> #NAME? | K9: =VLOOKUP(J9,'Bảng Đơn vị'!$A$2:$B$10,2,1) -> #NAME? | L9: 45674 | M9: 2025
A10: 9 | C10: =IF(B10<>"",B10,C9) -> Đạo hàm Newton cho hàm một biến số thực và ứng dụng | D10: Đặng Kim Anh | E10: 3110124002 | I10: KHOA TOÁN (14 đề tài) | J10: =IFS( ISNUMBER(SEARCH("toán",I10)),"Khoa Toán - Tin, Trường ĐHSP", ISNUMBER(SEARCH("tin",I10)),"Khoa Toán - Tin, Trường ĐHSP", ISNUMBER(SEARCH("lý",I10)),"Khoa Lý - Hóa, Trường ĐHSP", ISNUMBER(SEARCH("hóa",I10)),"Khoa Lý - Hóa, Trường ĐHSP", ISNUMBER(SEARCH("ngữ văn",I10)),"Khoa Ngữ văn - Truyền thông, Trường ĐHSP", ISNUMBER(SEARCH("sử",I10)),"Khoa Sử - Địa - Chính trị, Trường ĐHSP", ISNUMBER(SEARCH("địa",I10)),"Khoa Sử - Địa - Chính trị, Trường ĐHSP", ISNUMBER(SEARCH("chính trị",I10)),"Khoa Sử - Địa - Chính trị, Trường ĐHSP", ISNUMBER(SEARCH("sinh",I10)),"Khoa Sinh - Nông nghiệp - Môi trường, Trường ĐHSP", ISNUMBER(SEARCH("tiểu học",I10)),"Khoa Giáo dục Tiểu học - Mầm non, Trường ĐHSP", ISNUMBER(SEARCH("mầm non",I10)),"Khoa Giáo dục Tiểu học - Mầm non, Trường ĐHSP", ISNUMBER(SEARCH("nghệ thuật",I10)),"Khoa Giáo dục Nghệ thuật - Thể chất, Trường ĐHSP", ISNUMBER(SEARCH("tâm lý",I10)),"Khoa Tâm lý - Giáo dục - Công tác Xã hội, Trường ĐHSP" ) -> #NAME? | K10: =VLOOKUP(J10,'Bảng Đơn vị'!$A$2:$B$10,2,1) -> #NAME? | L10: 45675 | M10: 2025
A11: 10 | C11: =IF(B11<>"",B11,C10) -> Đạo hàm Newton cho hàm một biến số thực và ứng dụng | D11: Ông Hoàng Anh Kiệt | E11: 3110124034 | I11: KHOA TOÁN (14 đề tài) | J11: =IFS( ISNUMBER(SEARCH("toán",I11)),"Khoa Toán - Tin, Trường ĐHSP", ISNUMBER(SEARCH("tin",I11)),"Khoa Toán - Tin, Trường ĐHSP", ISNUMBER(SEARCH("lý",I11)),"Khoa Lý - Hóa, Trường ĐHSP", ISNUMBER(SEARCH("hóa",I11)),"Khoa Lý - Hóa, Trường ĐHSP", ISNUMBER(SEARCH("ngữ văn",I11)),"Khoa Ngữ văn - Truyền thông, Trường ĐHSP", ISNUMBER(SEARCH("sử",I11)),"Khoa Sử - Địa - Chính trị, Trường ĐHSP", ISNUMBER(SEARCH("địa",I11)),"Khoa Sử - Địa - Chính trị, Trường ĐHSP", ISNUMBER(SEARCH("chính trị",I11)),"Khoa Sử - Địa - Chính trị, Trường ĐHSP", ISNUMBER(SEARCH("sinh",I11)),"Khoa Sinh - Nông nghiệp - Môi trường, Trường ĐHSP", ISNUMBER(SEARCH("tiểu học",I11)),"Khoa Giáo dục Tiểu học - Mầm non, Trường ĐHSP", ISNUMBER(SEARCH("mầm non",I11)),"Khoa Giáo dục Tiểu học - Mầm non, Trường ĐHSP", ISNUMBER(SEARCH("nghệ thuật",I11)),"Khoa Giáo dục Nghệ thuật - Thể chất, Trường ĐHSP", ISNUMBER(SEARCH("tâm lý",I11)),"Khoa Tâm lý - Giáo dục - Công tác Xã hội, Trường ĐHSP" ) -> #NAME? | K11: =VLOOKUP(J11,'Bảng Đơn vị'!$A$2:$B$10,2,1) -> #NAME? | L11: 45676 | M11: 2025
A12: 11 | B12: Vấn đề xấp xỉ trơn hàm điều hoà dưới một biến phức | C12: =IF(B12<>"",B12,C11) -> Vấn đề xấp xỉ trơn hàm điều hoà dưới một biến phức | D12: Bùi Lê Hương Thảo | E12: 3110123084 | F12: 23ST1 | G12: TS. Hoàng Nhật Quy | I12: KHOA TOÁN (14 đề tài) | J12: =IFS( ISNUMBER(SEARCH("toán",I12)),"Khoa Toán - Tin, Trường ĐHSP", ISNUMBER(SEARCH("tin",I12)),"Khoa Toán - Tin, Trường ĐHSP", ISNUMBER(SEARCH("lý",I12)),"Khoa Lý - Hóa, Trường ĐHSP", ISNUMBER(SEARCH("hóa",I12)),"Khoa Lý - Hóa, Trường ĐHSP", ISNUMBER(SEARCH("ngữ văn",I12)),"Khoa Ngữ văn - Truyền thông, Trường ĐHSP", ISNUMBER(SEARCH("sử",I12)),"Khoa Sử - Địa - Chính trị, Trường ĐHSP", ISNUMBER(SEARCH("địa",I12)),"Khoa Sử - Địa - Chính trị, Trường ĐHSP", ISNUMBER(SEARCH("chính trị",I12)),"Khoa Sử - Địa - Chính trị, Trường ĐHSP", ISNUMBER(SEARCH("sinh",I12)),"Khoa Sinh - Nông nghiệp - Môi trường, Trường ĐHSP", ISNUMBER(SEARCH("tiểu học",I12)),"Khoa Giáo dục Tiểu học - Mầm non, Trường ĐHSP", ISNUMBER(SEARCH("mầm non",I12)),"Khoa Giáo dục Tiểu học - Mầm non, Trường ĐHSP", ISNUMBER(SEARCH("nghệ thuật",I12)),"Khoa Giáo dục Nghệ thuật - Thể chất, Trường ĐHSP", ISNUMBER(SEARCH("tâm lý",I12)),"Khoa Tâm lý - Giáo dục - Công tác Xã hội, Trường ĐHSP" ) -> #NAME? | K12: =VLOOKUP(J12,'Bảng Đơn vị'!$A$2:$B$10,2,1) -> #NAME? | L12: 45677 | M12: 2025
A13: 12 | C13: =IF(B13<>"",B13,C12) -> Vấn đề xấp xỉ trơn hàm điều hoà dưới một biến phức | D13: Phan Huy Phúc | E13: 3110123076 | F13: 23ST1 | I13: KHOA TOÁN (14 đề tài) | J13: =IFS( ISNUMBER(SEARCH("toán",I13)),"Khoa Toán - Tin, Trường ĐHSP", ISNUMBER(SEARCH("tin",I13)),"Khoa Toán - Tin, Trường ĐHSP", ISNUMBER(SEARCH("lý",I13)),"Khoa Lý - Hóa, Trường ĐHSP", ISNUMBER(SEARCH("hóa",I13)),"Khoa Lý - Hóa, Trường ĐHSP", ISNUMBER(SEARCH("ngữ văn",I13)),"Khoa Ngữ văn - Truyền thông, Trường ĐHSP", ISNUMBER(SEARCH("sử",I13)),"Khoa Sử - Địa - Chính trị, Trường ĐHSP", ISNUMBER(SEARCH("địa",I13)),"Khoa Sử - Địa - Chính trị, Trường ĐHSP", ISNUMBER(SEARCH("chính trị",I13)),"Khoa Sử - Địa - Chính trị, Trường ĐHSP", ISNUMBER(SEARCH("sinh",I13)),"Khoa Sinh - Nông nghiệp - Môi trường, Trường ĐHSP", ISNUMBER(SEARCH("tiểu học",I13)),"Khoa Giáo dục Tiểu học - Mầm non, Trường ĐHSP", ISNUMBER(SEARCH("mầm non",I13)),"Khoa Giáo dục Tiểu học - Mầm non, Trường ĐHSP", ISNUMBER(SEARCH("nghệ thuật",I13)),"Khoa Giáo dục Nghệ thuật - Thể chất, Trường ĐHSP", ISNUMBER(SEARCH("tâm lý",I13)),"Khoa Tâm lý - Giáo dục - Công tác Xã hội, Trường ĐHSP" ) -> #NAME? | K13: =VLOOKUP(J13,'Bảng Đơn vị'!$A$2:$B$10,2,1) -> #NAME? | L13: 45678 | M13: 2025
A14: 13 | C14: =IF(B14<>"",B14,C13) -> Vấn đề xấp xỉ trơn hàm điều hoà dưới một biến phức | D14: Tạ Tiểu Mi | E14: 3110123057 | F14: 23ST1 | I14: KHOA TOÁN (14 đề tài) | J14: =IFS( ISNUMBER(SEARCH("toán",I14)),"Khoa Toán - Tin, Trường ĐHSP", ISNUMBER(SEARCH("tin",I14)),"Khoa Toán - Tin, Trường ĐHSP", ISNUMBER(SEARCH("lý",I14)),"Khoa Lý - Hóa, Trường ĐHSP", ISNUMBER(SEARCH("hóa",I14)),"Khoa Lý - Hóa, Trường ĐHSP", ISNUMBER(SEARCH("ngữ văn",I14)),"Khoa Ngữ văn - Truyền thông, Trường ĐHSP", ISNUMBER(SEARCH("sử",I14)),"Khoa Sử - Địa - Chính trị, Trường ĐHSP", ISNUMBER(SEARCH("địa",I14)),"Khoa Sử - Địa - Chính trị, Trường ĐHSP", ISNUMBER(SEARCH("chính trị",I14)),"Khoa Sử - Địa - Chính trị, Trường ĐHSP", ISNUMBER(SEARCH("sinh",I14)),"Khoa Sinh - Nông nghiệp - Môi trường, Trường ĐHSP", ISNUMBER(SEARCH("tiểu học",I14)),"Khoa Giáo dục Tiểu học - Mầm non, Trường ĐHSP", ISNUMBER(SEARCH("mầm non",I14)),"Khoa Giáo dục Tiểu học - Mầm non, Trường ĐHSP", ISNUMBER(SEARCH("nghệ thuật",I14)),"Khoa Giáo dục Nghệ thuật - Thể chất, Trường ĐHSP", ISNUMBER(SEARCH("tâm lý",I14)),"Khoa Tâm lý - Giáo dục - Công tác Xã hội, Trường ĐHSP" ) -> #NAME? | K14: =VLOOKUP(J14,'Bảng Đơn vị'!$A$2:$B$10,2,1) -> #NAME? | L14: 45679 | M14: 2025
A15: 14 | C15: =IF(B15<>"",B15,C14) -> Vấn đề xấp xỉ trơn hàm điều hoà dưới một biến phức | D15: Trần Mạnh Tân | E15: 3110123082 | F15: 23ST1 | I15: KHOA TOÁN (14 đề tài) | J15: =IFS( ISNUMBER(SEARCH("toán",I15)),"Khoa Toán - Tin, Trường ĐHSP", ISNUMBER(SEARCH("tin",I15)),"Khoa Toán - Tin, Trường ĐHSP", ISNUMBER(SEARCH("lý",I15)),"Khoa Lý - Hóa, Trường ĐHSP", ISNUMBER(SEARCH("hóa",I15)),"Khoa Lý - Hóa, Trường ĐHSP", ISNUMBER(SEARCH("ngữ văn",I15)),"Khoa Ngữ văn - Truyền thông, Trường ĐHSP", ISNUMBER(SEARCH("sử",I15)),"Khoa Sử - Địa - Chính trị, Trường ĐHSP", ISNUMBER(SEARCH("địa",I15)),"Khoa Sử - Địa - Chính trị, Trường ĐHSP", ISNUMBER(SEARCH("chính trị",I15)),"Khoa Sử - Địa - Chính trị, Trường ĐHSP", ISNUMBER(SEARCH("sinh",I15)),"Khoa Sinh - Nông nghiệp - Môi trường, Trường ĐHSP", ISNUMBER(SEARCH("tiểu học",I15)),"Khoa Giáo dục Tiểu học - Mầm non, Trường ĐHSP", ISNUMBER(SEARCH("mầm non",I15)),"Khoa Giáo dục Tiểu học - Mầm non, Trường ĐHSP", ISNUMBER(SEARCH("nghệ thuật",I15)),"Khoa Giáo dục Nghệ thuật - Thể chất, Trường ĐHSP", ISNUMBER(SEARCH("tâm lý",I15)),"Khoa Tâm lý - Giáo dục - Công tác Xã hội, Trường ĐHSP" ) -> #NAME? | K15: =VLOOKUP(J15,'Bảng Đơn vị'!$A$2:$B$10,2,1) -> #NAME? | L15: 45680 | M15: 2025
A16: 15 | C16: =IF(B16<>"",B16,C15) -> Vấn đề xấp xỉ trơn hàm điều hoà dưới một biến phức | D16: Hồ Duy Nguyên | E16: 3110121044 | F16: 21ST1 | I16: KHOA TOÁN (14 đề tài) | J16: =IFS( ISNUMBER(SEARCH("toán",I16)),"Khoa Toán - Tin, Trường ĐHSP", ISNUMBER(SEARCH("tin",I16)),"Khoa Toán - Tin, Trường ĐHSP", ISNUMBER(SEARCH("lý",I16)),"Khoa Lý - Hóa, Trường ĐHSP", ISNUMBER(SEARCH("hóa",I16)),"Khoa Lý - Hóa, Trường ĐHSP", ISNUMBER(SEARCH("ngữ văn",I16)),"Khoa Ngữ văn - Truyền thông, Trường ĐHSP", ISNUMBER(SEARCH("sử",I16)),"Khoa Sử - Địa - Chính trị, Trường ĐHSP", ISNUMBER(SEARCH("địa",I16)),"Khoa Sử - Địa - Chính trị, Trường ĐHSP", ISNUMBER(SEARCH("chính trị",I16)),"Khoa Sử - Địa - Chính trị, Trường ĐHSP", ISNUMBER(SEARCH("sinh",I16)),"Khoa Sinh - Nông nghiệp - Môi trường, Trường ĐHSP", ISNUMBER(SEARCH("tiểu học",I16)),"Khoa Giáo dục Tiểu học - Mầm non, Trường ĐHSP", ISNUMBER(SEARCH("mầm non",I16)),"Khoa Giáo dục Tiểu học - Mầm non, Trường ĐHSP", ISNUMBER(SEARCH("nghệ thuật",I16)),"Khoa Giáo dục Nghệ thuật - Thể chất, Trường ĐHSP", ISNUMBER(SEARCH("tâm lý",I16)),"Khoa Tâm lý - Giáo dục - Công tác Xã hội, Trường ĐHSP" ) -> #NAME? | K16: =VLOOKUP(J16,'Bảng Đơn vị'!$A$2:$B$10,2,1) -> #NAME? | L16: 45681 | M16: 2025
A17: 16 | B17: Ứng dụng thuật toán Euclid khai triển liên phân số của số thực và lập mật mã | C17: =IF(B17<>"",B17,C16) -> Ứng dụng thuật toán Euclid khai triển liên phân số của số thực và lập mật mã | D17: Phạm Mẫn Minh | E17: 3110123059 | F17: 23ST1 | G17: TS. Hoàng Nhật Quy | I17: KHOA TOÁN (14 đề tài) | J17: =IFS( ISNUMBER(SEARCH("toán",I17)),"Khoa Toán - Tin, Trường ĐHSP", ISNUMBER(SEARCH("tin",I17)),"Khoa Toán - Tin, Trường ĐHSP", ISNUMBER(SEARCH("lý",I17)),"Khoa Lý - Hóa, Trường ĐHSP", ISNUMBER(SEARCH("hóa",I17)),"Khoa Lý - Hóa, Trường ĐHSP", ISNUMBER(SEARCH("ngữ văn",I17)),"Khoa Ngữ văn - Truyền thông, Trường ĐHSP", ISNUMBER(SEARCH("sử",I17)),"Khoa Sử - Địa - Chính trị, Trường ĐHSP", ISNUMBER(SEARCH("địa",I17)),"Khoa Sử - Địa - Chính trị, Trường ĐHSP", ISNUMBER(SEARCH("chính trị",I17)),"Khoa Sử - Địa - Chính trị, Trường ĐHSP", ISNUMBER(SEARCH("sinh",I17)),"Khoa Sinh - Nông nghiệp - Môi trường, Trường ĐHSP", ISNUMBER(SEARCH("tiểu học",I17)),"Khoa Giáo dục Tiểu học - Mầm non, Trường ĐHSP", ISNUMBER(SEARCH("mầm non",I17)),"Khoa Giáo dục Tiểu học - Mầm non, Trường ĐHSP", ISNUMBER(SEARCH("nghệ thuật",I17)),"Khoa Giáo dục Nghệ thuật - Thể chất, Trường ĐHSP", ISNUMBER(SEARCH("tâm lý",I17)),"Khoa Tâm lý - Giáo dục - Công tác Xã hội, Trường ĐHSP" ) -> #NAME? | K17: =VLOOKUP(J17,'Bảng Đơn vị'!$A$2:$B$10,2,1) -> #NAME? | L17: 45682 | M17: 2025
A18: 17 | C18: =IF(B18<>"",B18,C17) -> Ứng dụng thuật toán Euclid khai triển liên phân số của số thực và lập mật mã | D18: Võ Thị Thanh Giang | E18: 3110123019 | F18: 23ST1 | I18: KHOA TOÁN (14 đề tài) | J18: =IFS( ISNUMBER(SEARCH("toán",I18)),"Khoa Toán - Tin, Trường ĐHSP", ISNUMBER(SEARCH("tin",I18)),"Khoa Toán - Tin, Trường ĐHSP", ISNUMBER(SEARCH("lý",I18)),"Khoa Lý - Hóa, Trường ĐHSP", ISNUMBER(SEARCH("hóa",I18)),"Khoa Lý - Hóa, Trường ĐHSP", ISNUMBER(SEARCH("ngữ văn",I18)),"Khoa Ngữ văn - Truyền thông, Trường ĐHSP", ISNUMBER(SEARCH("sử",I18)),"Khoa Sử - Địa - Chính trị, Trường ĐHSP", ISNUMBER(SEARCH("địa",I18)),"Khoa Sử - Địa - Chính trị, Trường ĐHSP", ISNUMBER(SEARCH("chính trị",I18)),"Khoa Sử - Địa - Chính trị, Trường ĐHSP", ISNUMBER(SEARCH("sinh",I18)),"Khoa Sinh - Nông nghiệp - Môi trường, Trường ĐHSP", ISNUMBER(SEARCH("tiểu học",I18)),"Khoa Giáo dục Tiểu học - Mầm non, Trường ĐHSP", ISNUMBER(SEARCH("mầm non",I18)),"Khoa Giáo dục Tiểu học - Mầm non, Trường ĐHSP", ISNUMBER(SEARCH("nghệ thuật",I18)),"Khoa Giáo dục Nghệ thuật - Thể chất, Trường ĐHSP", ISNUMBER(SEARCH("tâm lý",I18)),"Khoa Tâm lý - Giáo dục - Công tác Xã hội, Trường ĐHSP" ) -> #NAME? | K18: =VLOOKUP(J18,'Bảng Đơn vị'!$A$2:$B$10,2,1) -> #NAME? | L18: 45683 | M18: 2025
A19: 18 | C19: =IF(B19<>"",B19,C18) -> Ứng dụng thuật toán Euclid khai triển liên phân số của số thực và lập mật mã | D19: Ngô Thị Thu Ba | E19: 3110123005 | F19: 23ST1 | I19: KHOA TOÁN (14 đề tài) | J19: =IFS( ISNUMBER(SEARCH("toán",I19)),"Khoa Toán - Tin, Trường ĐHSP", ISNUMBER(SEARCH("tin",I19)),"Khoa Toán - Tin, Trường ĐHSP", ISNUMBER(SEARCH("lý",I19)),"Khoa Lý - Hóa, Trường ĐHSP", ISNUMBER(SEARCH("hóa",I19)),"Khoa Lý - Hóa, Trường ĐHSP", ISNUMBER(SEARCH("ngữ văn",I19)),"Khoa Ngữ văn - Truyền thông, Trường ĐHSP", ISNUMBER(SEARCH("sử",I19)),"Khoa Sử - Địa - Chính trị, Trường ĐHSP", ISNUMBER(SEARCH("địa",I19)),"Khoa Sử - Địa - Chính trị, Trường ĐHSP", ISNUMBER(SEARCH("chính trị",I19)),"Khoa Sử - Địa - Chính trị, Trường ĐHSP", ISNUMBER(SEARCH("sinh",I19)),"Khoa Sinh - Nông nghiệp - Môi trường, Trường ĐHSP", ISNUMBER(SEARCH("tiểu học",I19)),"Khoa Giáo dục Tiểu học - Mầm non, Trường ĐHSP", ISNUMBER(SEARCH("mầm non",I19)),"Khoa Giáo dục Tiểu học - Mầm non, Trường ĐHSP", ISNUMBER(SEARCH("nghệ thuật",I19)),"Khoa Giáo dục Nghệ thuật - Thể chất, Trường ĐHSP", ISNUMBER(SEARCH("tâm lý",I19)),"Khoa Tâm lý - Giáo dục - Công tác Xã hội, Trường ĐHSP" ) -> #NAME? | K19: =VLOOKUP(J19,'Bảng Đơn vị'!$A$2:$B$10,2,1) -> #NAME? | L19: 45684 | M19: 2025
A20: 19 | C20: =IF(B20<>"",B20,C19) -> Ứng dụng thuật toán Euclid khai triển liên phân số của số thực và lập mật mã | D20: Nguyễn Văn Bình | E20: 3110122004 | F20: 22ST2 | I20: KHOA TOÁN (14 đề tài) | J20: =IFS( ISNUMBER(SEARCH("toán",I20)),"Khoa Toán - Tin, Trường ĐHSP", ISNUMBER(SEARCH("tin",I20)),"Khoa Toán - Tin, Trường ĐHSP", ISNUMBER(SEARCH("lý",I20)),"Khoa Lý - Hóa, Trường ĐHSP", ISNUMBER(SEARCH("hóa",I20)),"Khoa Lý - Hóa, Trường ĐHSP", ISNUMBER(SEARCH("ngữ văn",I20)),"Khoa Ngữ văn - Truyền thông, Trường ĐHSP", ISNUMBER(SEARCH("sử",I20)),"Khoa Sử - Địa - Chính trị, Trường ĐHSP", ISNUMBER(SEARCH("địa",I20)),"Khoa Sử - Địa - Chính trị, Trường ĐHSP", ISNUMBER(SEARCH("chính trị",I20)),"Khoa Sử - Địa - Chính trị, Trường ĐHSP", ISNUMBER(SEARCH("sinh",I20)),"Khoa Sinh - Nông nghiệp - Môi trường, Trường ĐHSP", ISNUMBER(SEARCH("tiểu học",I20)),"Khoa Giáo dục Tiểu học - Mầm non, Trường ĐHSP", ISNUMBER(SEARCH("mầm non",I20)),"Khoa Giáo dục Tiểu học - Mầm non, Trường ĐHSP", ISNUMBER(SEARCH("nghệ thuật",I20)),"Khoa Giáo dục Nghệ thuật - Thể chất, Trường ĐHSP", ISNUMBER(SEARCH("tâm lý",I20)),"Khoa Tâm lý - Giáo dục - Công tác Xã hội, Trường ĐHSP" ) -> #NAME? | K20: =VLOOKUP(J20,'Bảng Đơn vị'!$A$2:$B$10,2,1) -> #NAME? | L20: 45685 | M20: 2025
A21: 20 | C21: =IF(B21<>"",B21,C20) -> Ứng dụng thuật toán Euclid khai triển liên phân số của số thực và lập mật mã | D21: Nguyễn Hữu Thành | E21: 3110122078 | F21: 22ST2 | I21: KHOA TOÁN (14 đề tài) | J21: =IFS( ISNUMBER(SEARCH("toán",I21)),"Khoa Toán - Tin, Trường ĐHSP", ISNUMBER(SEARCH("tin",I21)),"Khoa Toán - Tin, Trường ĐHSP", ISNUMBER(SEARCH("lý",I21)),"Khoa Lý - Hóa, Trường ĐHSP", ISNUMBER(SEARCH("hóa",I21)),"Khoa Lý - Hóa, Trường ĐHSP", ISNUMBER(SEARCH("ngữ văn",I21)),"Khoa Ngữ văn - Truyền thông, Trường ĐHSP", ISNUMBER(SEARCH("sử",I21)),"Khoa Sử - Địa - Chính trị, Trường ĐHSP", ISNUMBER(SEARCH("địa",I21)),"Khoa Sử - Địa - Chính trị, Trường ĐHSP", ISNUMBER(SEARCH("chính trị",I21)),"Khoa Sử - Địa - Chính trị, Trường ĐHSP", ISNUMBER(SEARCH("sinh",I21)),"Khoa Sinh - Nông nghiệp - Môi trường, Trường ĐHSP", ISNUMBER(SEARCH("tiểu học",I21)),"Khoa Giáo dục Tiểu học - Mầm non, Trường ĐHSP", ISNUMBER(SEARCH("mầm non",I21)),"Khoa Giáo dục Tiểu học - Mầm non, Trường ĐHSP", ISNUMBER(SEARCH("nghệ thuật",I21)),"Khoa Giáo dục Nghệ thuật - Thể chất, Trường ĐHSP", ISNUMBER(SEARCH("tâm lý",I21)),"Khoa Tâm lý - Giáo dục - Công tác Xã hội, Trường ĐHSP" ) -> #NAME? | K21: =VLOOKUP(J21,'Bảng Đơn vị'!$A$2:$B$10,2,1) -> #NAME? | L21: 45686 | M21: 2025
A22: 21 | B22: Vấn đề kiểm duyệt dữ liệu trong nội dung thống kê ở cấp trung học cơ sở | C22: =IF(B22<>"",B22,C21) -> Vấn đề kiểm duyệt dữ liệu trong nội dung thống kê ở cấp trung học cơ sở | D22: Lê Vũ Khoa | E22: 3110122039 | F22: 22ST2 | G22: TS. Tôn Thất Tú | I22: KHOA TOÁN (14 đề tài) | J22: =IFS( ISNUMBER(SEARCH("toán",I22)),"Khoa Toán - Tin, Trường ĐHSP", ISNUMBER(SEARCH("tin",I22)),"Khoa Toán - Tin, Trường ĐHSP", ISNUMBER(SEARCH("lý",I22)),"Khoa Lý - Hóa, Trường ĐHSP", ISNUMBER(SEARCH("hóa",I22)),"Khoa Lý - Hóa, Trường ĐHSP", ISNUMBER(SEARCH("ngữ văn",I22)),"Khoa Ngữ văn - Truyền thông, Trường ĐHSP", ISNUMBER(SEARCH("sử",I22)),"Khoa Sử - Địa - Chính trị, Trường ĐHSP", ISNUMBER(SEARCH("địa",I22)),"Khoa Sử - Địa - Chính trị, Trường ĐHSP", ISNUMBER(SEARCH("chính trị",I22)),"Khoa Sử - Địa - Chính trị, Trường ĐHSP", ISNUMBER(SEARCH("sinh",I22)),"Khoa Sinh - Nông nghiệp - Môi trường, Trường ĐHSP", ISNUMBER(SEARCH("tiểu học",I22)),"Khoa Giáo dục Tiểu học - Mầm non, Trường ĐHSP", ISNUMBER(SEARCH("mầm non",I22)),"Khoa Giáo dục Tiểu học - Mầm non, Trường ĐHSP", ISNUMBER(SEARCH("nghệ thuật",I22)),"Khoa Giáo dục Nghệ thuật - Thể chất, Trường ĐHSP", ISNUMBER(SEARCH("tâm lý",I22)),"Khoa Tâm lý - Giáo dục - Công tác Xã hội, Trường ĐHSP" ) -> #NAME? | K22: =VLOOKUP(J22,'Bảng Đơn vị'!$A$2:$B$10,2,1) -> #NAME? | L22: 45687 | M22: 2025
A23: 22 | C23: =IF(B23<>"",B23,C22) -> Vấn đề kiểm duyệt dữ liệu trong nội dung thống kê ở cấp trung học cơ sở | D23: Lê Bùi Quỳnh Chi | E23: 3110122006 | F23: 22ST2 | I23: KHOA TOÁN (14 đề tài) | J23: =IFS( ISNUMBER(SEARCH("toán",I23)),"Khoa Toán - Tin, Trường ĐHSP", ISNUMBER(SEARCH("tin",I23)),"Khoa Toán - Tin, Trường ĐHSP", ISNUMBER(SEARCH("lý",I23)),"Khoa Lý - Hóa, Trường ĐHSP", ISNUMBER(SEARCH("hóa",I23)),"Khoa Lý - Hóa, Trường ĐHSP", ISNUMBER(SEARCH("ngữ văn",I23)),"Khoa Ngữ văn - Truyền thông, Trường ĐHSP", ISNUMBER(SEARCH("sử",I23)),"Khoa Sử - Địa - Chính trị, Trường ĐHSP", ISNUMBER(SEARCH("địa",I23)),"Khoa Sử - Địa - Chính trị, Trường ĐHSP", ISNUMBER(SEARCH("chính trị",I23)),"Khoa Sử - Địa - Chính trị, Trường ĐHSP", ISNUMBER(SEARCH("sinh",I23)),"Khoa Sinh - Nông nghiệp - Môi trường, Trường ĐHSP", ISNUMBER(SEARCH("tiểu học",I23)),"Khoa Giáo dục Tiểu học - Mầm non, Trường ĐHSP", ISNUMBER(SEARCH("mầm non",I23)),"Khoa Giáo dục Tiểu học - Mầm non, Trường ĐHSP", ISNUMBER(SEARCH("nghệ thuật",I23)),"Khoa Giáo dục Nghệ thuật - Thể chất, Trường ĐHSP", ISNUMBER(SEARCH("tâm lý",I23)),"Khoa Tâm lý - Giáo dục - Công tác Xã hội, Trường ĐHSP" ) -> #NAME? | K23: =VLOOKUP(J23,'Bảng Đơn vị'!$A$2:$B$10,2,1) -> #NAME? | L23: 45688 | M23: 2025
A24: 23 | C24: =IF(B24<>"",B24,C23) -> Vấn đề kiểm duyệt dữ liệu trong nội dung thống kê ở cấp trung học cơ sở | D24: Lê Thành Nhân Hà | E24: 3110123068 | F24: 23ST1 | I24: KHOA TOÁN (14 đề tài) | J24: =IFS( ISNUMBER(SEARCH("toán",I24)),"Khoa Toán - Tin, Trường ĐHSP", ISNUMBER(SEARCH("tin",I24)),"Khoa Toán - Tin, Trường ĐHSP", ISNUMBER(SEARCH("lý",I24)),"Khoa Lý - Hóa, Trường ĐHSP", ISNUMBER(SEARCH("hóa",I24)),"Khoa Lý - Hóa, Trường ĐHSP", ISNUMBER(SEARCH("ngữ văn",I24)),"Khoa Ngữ văn - Truyền thông, Trường ĐHSP", ISNUMBER(SEARCH("sử",I24)),"Khoa Sử - Địa - Chính trị, Trường ĐHSP", ISNUMBER(SEARCH("địa",I24)),"Khoa Sử - Địa - Chính trị, Trường ĐHSP", ISNUMBER(SEARCH("chính trị",I24)),"Khoa Sử - Địa - Chính trị, Trường ĐHSP", ISNUMBER(SEARCH("sinh",I24)),"Khoa Sinh - Nông nghiệp - Môi trường, Trường ĐHSP", ISNUMBER(SEARCH("tiểu học",I24)),"Khoa Giáo dục Tiểu học - Mầm non, Trường ĐHSP", ISNUMBER(SEARCH("mầm non",I24)),"Khoa Giáo dục Tiểu học - Mầm non, Trường ĐHSP", ISNUMBER(SEARCH("nghệ thuật",I24)),"Khoa Giáo dục Nghệ thuật - Thể chất, Trường ĐHSP", ISNUMBER(SEARCH("tâm lý",I24)),"Khoa Tâm lý - Giáo dục - Công tác Xã hội, Trường ĐHSP" ) -> #NAME? | K24: =VLOOKUP(J24,'Bảng Đơn vị'!$A$2:$B$10,2,1) -> #NAME? | L24: 45689 | M24: 2025
A25: 24 | C25: =IF(B25<>"",B25,C24) -> Vấn đề kiểm duyệt dữ liệu trong nội dung thống kê ở cấp trung học cơ sở | D25: Trương Khánh Linh | E25: 3110124035 | F25: 24ST1 | I25: KHOA TOÁN (14 đề tài) | J25: =IFS( ISNUMBER(SEARCH("toán",I25)),"Khoa Toán - Tin, Trường ĐHSP", ISNUMBER(SEARCH("tin",I25)),"Khoa Toán - Tin, Trường ĐHSP", ISNUMBER(SEARCH("lý",I25)),"Khoa Lý - Hóa, Trường ĐHSP", ISNUMBER(SEARCH("hóa",I25)),"Khoa Lý - Hóa, Trường ĐHSP", ISNUMBER(SEARCH("ngữ văn",I25)),"Khoa Ngữ văn - Truyền thông, Trường ĐHSP", ISNUMBER(SEARCH("sử",I25)),"Khoa Sử - Địa - Chính trị, Trường ĐHSP", ISNUMBER(SEARCH("địa",I25)),"Khoa Sử - Địa - Chính trị, Trường ĐHSP", ISNUMBER(SEARCH("chính trị",I25)),"Khoa Sử - Địa - Chính trị, Trường ĐHSP", ISNUMBER(SEARCH("sinh",I25)),"Khoa Sinh - Nông nghiệp - Môi trường, Trường ĐHSP", ISNUMBER(SEARCH("tiểu học",I25)),"Khoa Giáo dục Tiểu học - Mầm non, Trường ĐHSP", ISNUMBER(SEARCH("mầm non",I25)),"Khoa Giáo dục Tiểu học - Mầm non, Trường ĐHSP", ISNUMBER(SEARCH("nghệ thuật",I25)),"Khoa Giáo dục Nghệ thuật - Thể chất, Trường ĐHSP", ISNUMBER(SEARCH("tâm lý",I25)),"Khoa Tâm lý - Giáo dục - Công tác Xã hội, Trường ĐHSP" ) -> #NAME? | K25: =VLOOKUP(J25,'Bảng Đơn vị'!$A$2:$B$10,2,1) -> #NAME? | L25: 45690 | M25: 2025
A26: 25 | C26: =IF(B26<>"",B26,C25) -> Vấn đề kiểm duyệt dữ liệu trong nội dung thống kê ở cấp trung học cơ sở | D26: Nguyễn Phương Hoa | E26: 3110124019 | F26: 24ST1 | I26: KHOA TOÁN (14 đề tài) | J26: =IFS( ISNUMBER(SEARCH("toán",I26)),"Khoa Toán - Tin, Trường ĐHSP", ISNUMBER(SEARCH("tin",I26)),"Khoa Toán - Tin, Trường ĐHSP", ISNUMBER(SEARCH("lý",I26)),"Khoa Lý - Hóa, Trường ĐHSP", ISNUMBER(SEARCH("hóa",I26)),"Khoa Lý - Hóa, Trường ĐHSP", ISNUMBER(SEARCH("ngữ văn",I26)),"Khoa Ngữ văn - Truyền thông, Trường ĐHSP", ISNUMBER(SEARCH("sử",I26)),"Khoa Sử - Địa - Chính trị, Trường ĐHSP", ISNUMBER(SEARCH("địa",I26)),"Khoa Sử - Địa - Chính trị, Trường ĐHSP", ISNUMBER(SEARCH("chính trị",I26)),"Khoa Sử - Địa - Chính trị, Trường ĐHSP", ISNUMBER(SEARCH("sinh",I26)),"Khoa Sinh - Nông nghiệp - Môi trường, Trường ĐHSP", ISNUMBER(SEARCH("tiểu học",I26)),"Khoa Giáo dục Tiểu học - Mầm non, Trường ĐHSP", ISNUMBER(SEARCH("mầm non",I26)),"Khoa Giáo dục Tiểu học - Mầm non, Trường ĐHSP", ISNUMBER(SEARCH("nghệ thuật",I26)),"Khoa Giáo dục Nghệ thuật - Thể chất, Trường ĐHSP", ISNUMBER(SEARCH("tâm lý",I26)),"Khoa Tâm lý - Giáo dục - Công tác Xã hội, Trường ĐHSP" ) -> #NAME? | K26: =VLOOKUP(J26,'Bảng Đơn vị'!$A$2:$B$10,2,1) -> #NAME? | L26: 45691 | M26: 2025
A27: 26 | B27: Thuật toán K-means và ứng dụng | C27: =IF(B27<>"",B27,C26) -> Thuật toán K-means và ứng dụng | D27: Nguyễn Thị Lan Hương | E27: 3110524016 | F27: 24CKDL | G27: TS. Tôn Thất Tú | I27: KHOA TOÁN (14 đề tài) | J27: =IFS( ISNUMBER(SEARCH("toán",I27)),"Khoa Toán - Tin, Trường ĐHSP", ISNUMBER(SEARCH("tin",I27)),"Khoa Toán - Tin, Trường ĐHSP", ISNUMBER(SEARCH("lý",I27)),"Khoa Lý - Hóa, Trường ĐHSP", ISNUMBER(SEARCH("hóa",I27)),"Khoa Lý - Hóa, Trường ĐHSP", ISNUMBER(SEARCH("ngữ văn",I27)),"Khoa Ngữ văn - Truyền thông, Trường ĐHSP", ISNUMBER(SEARCH("sử",I27)),"Khoa Sử - Địa - Chính trị, Trường ĐHSP", ISNUMBER(SEARCH("địa",I27)),"Khoa Sử - Địa - Chính trị, Trường ĐHSP", ISNUMBER(SEARCH("chính trị",I27)),"Khoa Sử - Địa - Chính trị, Trường ĐHSP", ISNUMBER(SEARCH("sinh",I27)),"Khoa Sinh - Nông nghiệp - Môi trường, Trường ĐHSP", ISNUMBER(SEARCH("tiểu học",I27)),"Khoa Giáo dục Tiểu học - Mầm non, Trường ĐHSP", ISNUMBER(SEARCH("mầm non",I27)),"Khoa Giáo dục Tiểu học - Mầm non, Trường ĐHSP", ISNUMBER(SEARCH("nghệ thuật",I27)),"Khoa Giáo dục Nghệ thuật - Thể chất, Trường ĐHSP", ISNUMBER(SEARCH("tâm lý",I27)),"Khoa Tâm lý - Giáo dục - Công tác Xã hội, Trường ĐHSP" ) -> #NAME? | K27: =VLOOKUP(J27,'Bảng Đơn vị'!$A$2:$B$10,2,1) -> #NAME? | L27: 45692 | M27: 2025
A28: 27 | C28: =IF(B28<>"",B28,C27) -> Thuật toán K-means và ứng dụng | D28: Đoàn Nguyễn Dương | E28: 3110524008 | I28: KHOA TOÁN (14 đề tài) | J28: =IFS( ISNUMBER(SEARCH("toán",I28)),"Khoa Toán - Tin, Trường ĐHSP", ISNUMBER(SEARCH("tin",I28)),"Khoa Toán - Tin, Trường ĐHSP", ISNUMBER(SEARCH("lý",I28)),"Khoa Lý - Hóa, Trường ĐHSP", ISNUMBER(SEARCH("hóa",I28)),"Khoa Lý - Hóa, Trường ĐHSP", ISNUMBER(SEARCH("ngữ văn",I28)),"Khoa Ngữ văn - Truyền thông, Trường ĐHSP", ISNUMBER(SEARCH("sử",I28)),"Khoa Sử - Địa - Chính trị, Trường ĐHSP", ISNUMBER(SEARCH("địa",I28)),"Khoa Sử - Địa - Chính trị, Trường ĐHSP", ISNUMBER(SEARCH("chính trị",I28)),"Khoa Sử - Địa - Chính trị, Trường ĐHSP", ISNUMBER(SEARCH("sinh",I28)),"Khoa Sinh - Nông nghiệp - Môi trường, Trường ĐHSP", ISNUMBER(SEARCH("tiểu học",I28)),"Khoa Giáo dục Tiểu học - Mầm non, Trường ĐHSP", ISNUMBER(SEARCH("mầm non",I28)),"Khoa Giáo dục Tiểu học - Mầm non, Trường ĐHSP", ISNUMBER(SEARCH("nghệ thuật",I28)),"Khoa Giáo dục Nghệ thuật - Thể chất, Trường ĐHSP", ISNUMBER(SEARCH("tâm lý",I28)),"Khoa Tâm lý - Giáo dục - Công tác Xã hội, Trường ĐHSP" ) -> #NAME? | K28: =VLOOKUP(J28,'Bảng Đơn vị'!$A$2:$B$10,2,1) -> #NAME? | L28: 45693 | M28: 2025
A29: 28 | C29: =IF(B29<>"",B29,C28) -> Thuật toán K-means và ứng dụng | D29: Trịnh Phương Dung | E29: 3110524006 | I29: KHOA TOÁN (14 đề tài) | J29: =IFS( ISNUMBER(SEARCH("toán",I29)),"Khoa Toán - Tin, Trường ĐHSP", ISNUMBER(SEARCH("tin",I29)),"Khoa Toán - Tin, Trường ĐHSP", ISNUMBER(SEARCH("lý",I29)),"Khoa Lý - Hóa, Trường ĐHSP", ISNUMBER(SEARCH("hóa",I29)),"Khoa Lý - Hóa, Trường ĐHSP", ISNUMBER(SEARCH("ngữ văn",I29)),"Khoa Ngữ văn - Truyền thông, Trường ĐHSP", ISNUMBER(SEARCH("sử",I29)),"Khoa Sử - Địa - Chính trị, Trường ĐHSP", ISNUMBER(SEARCH("địa",I29)),"Khoa Sử - Địa - Chính trị, Trường ĐHSP", ISNUMBER(SEARCH("chính trị",I29)),"Khoa Sử - Địa - Chính trị, Trường ĐHSP", ISNUMBER(SEARCH("sinh",I29)),"Khoa Sinh - Nông nghiệp - Môi trường, Trường ĐHSP", ISNUMBER(SEARCH("tiểu học",I29)),"Khoa Giáo dục Tiểu học - Mầm non, Trường ĐHSP", ISNUMBER(SEARCH("mầm non",I29)),"Khoa Giáo dục Tiểu học - Mầm non, Trường ĐHSP", ISNUMBER(SEARCH("nghệ thuật",I29)),"Khoa Giáo dục Nghệ thuật - Thể chất, Trường ĐHSP", ISNUMBER(SEARCH("tâm lý",I29)),"Khoa Tâm lý - Giáo dục - Công tác Xã hội, Trường ĐHSP" ) -> #NAME? | K29: =VLOOKUP(J29,'Bảng Đơn vị'!$A$2:$B$10,2,1) -> #NAME? | L29: 45694 | M29: 2025
A30: 29 | C30: =IF(B30<>"",B30,C29) -> Thuật toán K-means và ứng dụng | D30: Trần Đăng Thịnh | E30: 3110524032 | I30: KHOA TOÁN (14 đề tài) | J30: =IFS( ISNUMBER(SEARCH("toán",I30)),"Khoa Toán - Tin, Trường ĐHSP", ISNUMBER(SEARCH("tin",I30)),"Khoa Toán - Tin, Trường ĐHSP", ISNUMBER(SEARCH("lý",I30)),"Khoa Lý - Hóa, Trường ĐHSP", ISNUMBER(SEARCH("hóa",I30)),"Khoa Lý - Hóa, Trường ĐHSP", ISNUMBER(SEARCH("ngữ văn",I30)),"Khoa Ngữ văn - Truyền thông, Trường ĐHSP", ISNUMBER(SEARCH("sử",I30)),"Khoa Sử - Địa - Chính trị, Trường ĐHSP", ISNUMBER(SEARCH("địa",I30)),"Khoa Sử - Địa - Chính trị, Trường ĐHSP", ISNUMBER(SEARCH("chính trị",I30)),"Khoa Sử - Địa - Chính trị, Trường ĐHSP", ISNUMBER(SEARCH("sinh",I30)),"Khoa Sinh - Nông nghiệp - Môi trường, Trường ĐHSP", ISNUMBER(SEARCH("tiểu học",I30)),"Khoa Giáo dục Tiểu học - Mầm non, Trường ĐHSP", ISNUMBER(SEARCH("mầm non",I30)),"Khoa Giáo dục Tiểu học - Mầm non, Trường ĐHSP", ISNUMBER(SEARCH("nghệ thuật",I30)),"Khoa Giáo dục Nghệ thuật - Thể chất, Trường ĐHSP", ISNUMBER(SEARCH("tâm lý",I30)),"Khoa Tâm lý - Giáo dục - Công tác Xã hội, Trường ĐHSP" ) -> #NAME? | K30: =VLOOKUP(J30,'Bảng Đơn vị'!$A$2:$B$10,2,1) -> #NAME? | L30: 45695 | M30: 2025
A31: 30 | C31: =IF(B31<>"",B31,C30) -> Thuật toán K-means và ứng dụng | D31: Đoàn Công Bảo Hiếu | E31: 3110524011 | I31: KHOA TOÁN (14 đề tài) | J31: =IFS( ISNUMBER(SEARCH("toán",I31)),"Khoa Toán - Tin, Trường ĐHSP", ISNUMBER(SEARCH("tin",I31)),"Khoa Toán - Tin, Trường ĐHSP", ISNUMBER(SEARCH("lý",I31)),"Khoa Lý - Hóa, Trường ĐHSP", ISNUMBER(SEARCH("hóa",I31)),"Khoa Lý - Hóa, Trường ĐHSP", ISNUMBER(SEARCH("ngữ văn",I31)),"Khoa Ngữ văn - Truyền thông, Trường ĐHSP", ISNUMBER(SEARCH("sử",I31)),"Khoa Sử - Địa - Chính trị, Trường ĐHSP", ISNUMBER(SEARCH("địa",I31)),"Khoa Sử - Địa - Chính trị, Trường ĐHSP", ISNUMBER(SEARCH("chính trị",I31)),"Khoa Sử - Địa - Chính trị, Trường ĐHSP", ISNUMBER(SEARCH("sinh",I31)),"Khoa Sinh - Nông nghiệp - Môi trường, Trường ĐHSP", ISNUMBER(SEARCH("tiểu học",I31)),"Khoa Giáo dục Tiểu học - Mầm non, Trường ĐHSP", ISNUMBER(SEARCH("mầm non",I31)),"Khoa Giáo dục Tiểu học - Mầm non, Trường ĐHSP", ISNUMBER(SEARCH("nghệ thuật",I31)),"Khoa Giáo dục Nghệ thuật - Thể chất, Trường ĐHSP", ISNUMBER(SEARCH("tâm lý",I31)),"Khoa Tâm lý - Giáo dục - Công tác Xã hội, Trường ĐHSP" ) -> #NAME? | K31: =VLOOKUP(J31,'Bảng Đơn vị'!$A$2:$B$10,2,1) -> #NAME? | L31: 45696 | M31: 2025
A32: 31 | B32: Mối quan hệ giữa các phủ trong không gian topo X với các phủ trong siêu không gian của X | C32: =IF(B32<>"",B32,C31) -> Mối quan hệ giữa các phủ trong không gian topo X với các phủ trong siêu không gian của X | D32: Nguyễn Xuân Trúc | E32: 3110121142 | F32: 21ST2 | G32: TS. Lương Quốc Tuyển | I32: KHOA TOÁN (14 đề tài) | J32: =IFS( ISNUMBER(SEARCH("toán",I32)),"Khoa Toán - Tin, Trường ĐHSP", ISNUMBER(SEARCH("tin",I32)),"Khoa Toán - Tin, Trường ĐHSP", ISNUMBER(SEARCH("lý",I32)),"Khoa Lý - Hóa, Trường ĐHSP", ISNUMBER(SEARCH("hóa",I32)),"Khoa Lý - Hóa, Trường ĐHSP", ISNUMBER(SEARCH("ngữ văn",I32)),"Khoa Ngữ văn - Truyền thông, Trường ĐHSP", ISNUMBER(SEARCH("sử",I32)),"Khoa Sử - Địa - Chính trị, Trường ĐHSP", ISNUMBER(SEARCH("địa",I32)),"Khoa Sử - Địa - Chính trị, Trường ĐHSP", ISNUMBER(SEARCH("chính trị",I32)),"Khoa Sử - Địa - Chính trị, Trường ĐHSP", ISNUMBER(SEARCH("sinh",I32)),"Khoa Sinh - Nông nghiệp - Môi trường, Trường ĐHSP", ISNUMBER(SEARCH("tiểu học",I32)),"Khoa Giáo dục Tiểu học - Mầm non, Trường ĐHSP", ISNUMBER(SEARCH("mầm non",I32)),"Khoa Giáo dục Tiểu học - Mầm non, Trường ĐHSP", ISNUMBER(SEARCH("nghệ thuật",I32)),"Khoa Giáo dục Nghệ thuật - Thể chất, Trường ĐHSP", ISNUMBER(SEARCH("tâm lý",I32)),"Khoa Tâm lý - Giáo dục - Công tác Xã hội, Trường ĐHSP" ) -> #NAME? | K32: =VLOOKUP(J32,'Bảng Đơn vị'!$A$2:$B$10,2,1) -> #NAME? | L32: 45697 | M32: 2025
A33: 32 | C33: =IF(B33<>"",B33,C32) -> Mối quan hệ giữa các phủ trong không gian topo X với các phủ trong siêu không gian của X | D33: Nguyễn Thị Hồng Phúc | E33: 3110122066 | F33: 22ST2 | I33: KHOA TOÁN (14 đề tài) | J33: =IFS( ISNUMBER(SEARCH("toán",I33)),"Khoa Toán - Tin, Trường ĐHSP", ISNUMBER(SEARCH("tin",I33)),"Khoa Toán - Tin, Trường ĐHSP", ISNUMBER(SEARCH("lý",I33)),"Khoa Lý - Hóa, Trường ĐHSP", ISNUMBER(SEARCH("hóa",I33)),"Khoa Lý - Hóa, Trường ĐHSP", ISNUMBER(SEARCH("ngữ văn",I33)),"Khoa Ngữ văn - Truyền thông, Trường ĐHSP", ISNUMBER(SEARCH("sử",I33)),"Khoa Sử - Địa - Chính trị, Trường ĐHSP", ISNUMBER(SEARCH("địa",I33)),"Khoa Sử - Địa - Chính trị, Trường ĐHSP", ISNUMBER(SEARCH("chính trị",I33)),"Khoa Sử - Địa - Chính trị, Trường ĐHSP", ISNUMBER(SEARCH("sinh",I33)),"Khoa Sinh - Nông nghiệp - Môi trường, Trường ĐHSP", ISNUMBER(SEARCH("tiểu học",I33)),"Khoa Giáo dục Tiểu học - Mầm non, Trường ĐHSP", ISNUMBER(SEARCH("mầm non",I33)),"Khoa Giáo dục Tiểu học - Mầm non, Trường ĐHSP", ISNUMBER(SEARCH("nghệ thuật",I33)),"Khoa Giáo dục Nghệ thuật - Thể chất, Trường ĐHSP", ISNUMBER(SEARCH("tâm lý",I33)),"Khoa Tâm lý - Giáo dục - Công tác Xã hội, Trường ĐHSP" ) -> #NAME? | K33: =VLOOKUP(J33,'Bảng Đơn vị'!$A$2:$B$10,2,1) -> #NAME? | L33: 45698 | M33: 2025
A34: 33 | B34: Các tính chất topo được xây dựng bởi sự hội tụ theo ideal | C34: =IF(B34<>"",B34,C33) -> Các tính chất topo được xây dựng bởi sự hội tụ theo ideal | D34: Nguyễn Thuận Hiếu | E34: 3110123033 | F34: 23ST2 | G34: TS. Lương Quốc Tuyển | I34: KHOA TOÁN (14 đề tài) | J34: =IFS( ISNUMBER(SEARCH("toán",I34)),"Khoa Toán - Tin, Trường ĐHSP", ISNUMBER(SEARCH("tin",I34)),"Khoa Toán - Tin, Trường ĐHSP", ISNUMBER(SEARCH("lý",I34)),"Khoa Lý - Hóa, Trường ĐHSP", ISNUMBER(SEARCH("hóa",I34)),"Khoa Lý - Hóa, Trường ĐHSP", ISNUMBER(SEARCH("ngữ văn",I34)),"Khoa Ngữ văn - Truyền thông, Trường ĐHSP", ISNUMBER(SEARCH("sử",I34)),"Khoa Sử - Địa - Chính trị, Trường ĐHSP", ISNUMBER(SEARCH("địa",I34)),"Khoa Sử - Địa - Chính trị, Trường ĐHSP", ISNUMBER(SEARCH("chính trị",I34)),"Khoa Sử - Địa - Chính trị, Trường ĐHSP", ISNUMBER(SEARCH("sinh",I34)),"Khoa Sinh - Nông nghiệp - Môi trường, Trường ĐHSP", ISNUMBER(SEARCH("tiểu học",I34)),"Khoa Giáo dục Tiểu học - Mầm non, Trường ĐHSP", ISNUMBER(SEARCH("mầm non",I34)),"Khoa Giáo dục Tiểu học - Mầm non, Trường ĐHSP", ISNUMBER(SEARCH("nghệ thuật",I34)),"Khoa Giáo dục Nghệ thuật - Thể chất, Trường ĐHSP", ISNUMBER(SEARCH("tâm lý",I34)),"Khoa Tâm lý - Giáo dục - Công tác Xã hội, Trường ĐHSP" ) -> #NAME? | K34: =VLOOKUP(J34,'Bảng Đơn vị'!$A$2:$B$10,2,1) -> #NAME? | L34: 45699 | M34: 2025
A35: 34 | C35: =IF(B35<>"",B35,C34) -> Các tính chất topo được xây dựng bởi sự hội tụ theo ideal | D35: Nguyễn Bảo Nhi | E35: 3110123070 | I35: KHOA TOÁN (14 đề tài) | J35: =IFS( ISNUMBER(SEARCH("toán",I35)),"Khoa Toán - Tin, Trường ĐHSP", ISNUMBER(SEARCH("tin",I35)),"Khoa Toán - Tin, Trường ĐHSP", ISNUMBER(SEARCH("lý",I35)),"Khoa Lý - Hóa, Trường ĐHSP", ISNUMBER(SEARCH("hóa",I35)),"Khoa Lý - Hóa, Trường ĐHSP", ISNUMBER(SEARCH("ngữ văn",I35)),"Khoa Ngữ văn - Truyền thông, Trường ĐHSP", ISNUMBER(SEARCH("sử",I35)),"Khoa Sử - Địa - Chính trị, Trường ĐHSP", ISNUMBER(SEARCH("địa",I35)),"Khoa Sử - Địa - Chính trị, Trường ĐHSP", ISNUMBER(SEARCH("chính trị",I35)),"Khoa Sử - Địa - Chính trị, Trường ĐHSP", ISNUMBER(SEARCH("sinh",I35)),"Khoa Sinh - Nông nghiệp - Môi trường, Trường ĐHSP", ISNUMBER(SEARCH("tiểu học",I35)),"Khoa Giáo dục Tiểu học - Mầm non, Trường ĐHSP", ISNUMBER(SEARCH("mầm non",I35)),"Khoa Giáo dục Tiểu học - Mầm non, Trường ĐHSP", ISNUMBER(SEARCH("nghệ thuật",I35)),"Khoa Giáo dục Nghệ thuật - Thể chất, Trường ĐHSP", ISNUMBER(SEARCH("tâm lý",I35)),"Khoa Tâm lý - Giáo dục - Công tác Xã hội, Trường ĐHSP" ) -> #NAME? | K35: =VLOOKUP(J35,'Bảng Đơn vị'!$A$2:$B$10,2,1) -> #NAME? | L35: 45700 | M35: 2025
A36: 35 | C36: =IF(B36<>"",B36,C35) -> Các tính chất topo được xây dựng bởi sự hội tụ theo ideal | D36: Lê Thị Thơ | E36: 3110123089 | I36: KHOA TOÁN (14 đề tài) | J36: =IFS( ISNUMBER(SEARCH("toán",I36)),"Khoa Toán - Tin, Trường ĐHSP", ISNUMBER(SEARCH("tin",I36)),"Khoa Toán - Tin, Trường ĐHSP", ISNUMBER(SEARCH("lý",I36)),"Khoa Lý - Hóa, Trường ĐHSP", ISNUMBER(SEARCH("hóa",I36)),"Khoa Lý - Hóa, Trường ĐHSP", ISNUMBER(SEARCH("ngữ văn",I36)),"Khoa Ngữ văn - Truyền thông, Trường ĐHSP", ISNUMBER(SEARCH("sử",I36)),"Khoa Sử - Địa - Chính trị, Trường ĐHSP", ISNUMBER(SEARCH("địa",I36)),"Khoa Sử - Địa - Chính trị, Trường ĐHSP", ISNUMBER(SEARCH("chính trị",I36)),"Khoa Sử - Địa - Chính trị, Trường ĐHSP", ISNUMBER(SEARCH("sinh",I36)),"Khoa Sinh - Nông nghiệp - Môi trường, Trường ĐHSP", ISNUMBER(SEARCH("tiểu học",I36)),"Khoa Giáo dục Tiểu học - Mầm non, Trường ĐHSP", ISNUMBER(SEARCH("mầm non",I36)),"Khoa Giáo dục Tiểu học - Mầm non, Trường ĐHSP", ISNUMBER(SEARCH("nghệ thuật",I36)),"Khoa Giáo dục Nghệ thuật - Thể chất, Trường ĐHSP", ISNUMBER(SEARCH("tâm lý",I36)),"Khoa Tâm lý - Giáo dục - Công tác Xã hội, Trường ĐHSP" ) -> #NAME? | K36: =VLOOKUP(J36,'Bảng Đơn vị'!$A$2:$B$10,2,1) -> #NAME? | L36: 45701 | M36: 2025
A37: 36 | C37: =IF(B37<>"",B37,C36) -> Các tính chất topo được xây dựng bởi sự hội tụ theo ideal | D37: Lê Thị Liên | E37: 3110123047 | I37: KHOA TOÁN (14 đề tài) | J37: =IFS( ISNUMBER(SEARCH("toán",I37)),"Khoa Toán - Tin, Trường ĐHSP", ISNUMBER(SEARCH("tin",I37)),"Khoa Toán - Tin, Trường ĐHSP", ISNUMBER(SEARCH("lý",I37)),"Khoa Lý - Hóa, Trường ĐHSP", ISNUMBER(SEARCH("hóa",I37)),"Khoa Lý - Hóa, Trường ĐHSP", ISNUMBER(SEARCH("ngữ văn",I37)),"Khoa Ngữ văn - Truyền thông, Trường ĐHSP", ISNUMBER(SEARCH("sử",I37)),"Khoa Sử - Địa - Chính trị, Trường ĐHSP", ISNUMBER(SEARCH("địa",I37)),"Khoa Sử - Địa - Chính trị, Trường ĐHSP", ISNUMBER(SEARCH("chính trị",I37)),"Khoa Sử - Địa - Chính trị, Trường ĐHSP", ISNUMBER(SEARCH("sinh",I37)),"Khoa Sinh - Nông nghiệp - Môi trường, Trường ĐHSP", ISNUMBER(SEARCH("tiểu học",I37)),"Khoa Giáo dục Tiểu học - Mầm non, Trường ĐHSP", ISNUMBER(SEARCH("mầm non",I37)),"Khoa Giáo dục Tiểu học - Mầm non, Trường ĐHSP", ISNUMBER(SEARCH("nghệ thuật",I37)),"Khoa Giáo dục Nghệ thuật - Thể chất, Trường ĐHSP", ISNUMBER(SEARCH("tâm lý",I37)),"Khoa Tâm lý - Giáo dục - Công tác Xã hội, Trường ĐHSP" ) -> #NAME? | K37: =VLOOKUP(J37,'Bảng Đơn vị'!$A$2:$B$10,2,1) -> #NAME? | L37: 45702 | M37: 2025
A38: 37 | B38: Phân tích nguyên sơ của idean | C38: =IF(B38<>"",B38,C37) -> Phân tích nguyên sơ của idean | D38: Trương Quốc Việt | E38: 3110122015 | F38: 22ST2 | G38: TS. Trần Nam Sinh | I38: KHOA TOÁN (14 đề tài) | J38: =IFS( ISNUMBER(SEARCH("toán",I38)),"Khoa Toán - Tin, Trường ĐHSP", ISNUMBER(SEARCH("tin",I38)),"Khoa Toán - Tin, Trường ĐHSP", ISNUMBER(SEARCH("lý",I38)),"Khoa Lý - Hóa, Trường ĐHSP", ISNUMBER(SEARCH("hóa",I38)),"Khoa Lý - Hóa, Trường ĐHSP", ISNUMBER(SEARCH("ngữ văn",I38)),"Khoa Ngữ văn - Truyền thông, Trường ĐHSP", ISNUMBER(SEARCH("sử",I38)),"Khoa Sử - Địa - Chính trị, Trường ĐHSP", ISNUMBER(SEARCH("địa",I38)),"Khoa Sử - Địa - Chính trị, Trường ĐHSP", ISNUMBER(SEARCH("chính trị",I38)),"Khoa Sử - Địa - Chính trị, Trường ĐHSP", ISNUMBER(SEARCH("sinh",I38)),"Khoa Sinh - Nông nghiệp - Môi trường, Trường ĐHSP", ISNUMBER(SEARCH("tiểu học",I38)),"Khoa Giáo dục Tiểu học - Mầm non, Trường ĐHSP", ISNUMBER(SEARCH("mầm non",I38)),"Khoa Giáo dục Tiểu học - Mầm non, Trường ĐHSP", ISNUMBER(SEARCH("nghệ thuật",I38)),"Khoa Giáo dục Nghệ thuật - Thể chất, Trường ĐHSP", ISNUMBER(SEARCH("tâm lý",I38)),"Khoa Tâm lý - Giáo dục - Công tác Xã hội, Trường ĐHSP" ) -> #NAME? | K38: =VLOOKUP(J38,'Bảng Đơn vị'!$A$2:$B$10,2,1) -> #NAME? | L38: 45703 | M38: 2025
A39: 38 | C39: =IF(B39<>"",B39,C38) -> Phân tích nguyên sơ của idean | D39: Trần Bảo Uyên | E39: 3110122100 | F39: 22ST1 | I39: KHOA TOÁN (14 đề tài) | J39: =IFS( ISNUMBER(SEARCH("toán",I39)),"Khoa Toán - Tin, Trường ĐHSP", ISNUMBER(SEARCH("tin",I39)),"Khoa Toán - Tin, Trường ĐHSP", ISNUMBER(SEARCH("lý",I39)),"Khoa Lý - Hóa, Trường ĐHSP", ISNUMBER(SEARCH("hóa",I39)),"Khoa Lý - Hóa, Trường ĐHSP", ISNUMBER(SEARCH("ngữ văn",I39)),"Khoa Ngữ văn - Truyền thông, Trường ĐHSP", ISNUMBER(SEARCH("sử",I39)),"Khoa Sử - Địa - Chính trị, Trường ĐHSP", ISNUMBER(SEARCH("địa",I39)),"Khoa Sử - Địa - Chính trị, Trường ĐHSP", ISNUMBER(SEARCH("chính trị",I39)),"Khoa Sử - Địa - Chính trị, Trường ĐHSP", ISNUMBER(SEARCH("sinh",I39)),"Khoa Sinh - Nông nghiệp - Môi trường, Trường ĐHSP", ISNUMBER(SEARCH("tiểu học",I39)),"Khoa Giáo dục Tiểu học - Mầm non, Trường ĐHSP", ISNUMBER(SEARCH("mầm non",I39)),"Khoa Giáo dục Tiểu học - Mầm non, Trường ĐHSP", ISNUMBER(SEARCH("nghệ thuật",I39)),"Khoa Giáo dục Nghệ thuật - Thể chất, Trường ĐHSP", ISNUMBER(SEARCH("tâm lý",I39)),"Khoa Tâm lý - Giáo dục - Công tác Xã hội, Trường ĐHSP" ) -> #NAME? | K39: =VLOOKUP(J39,'Bảng Đơn vị'!$A$2:$B$10,2,1) -> #NAME? | L39: 45704 | M39: 2025
A40: 39 | C40: =IF(B40<>"",B40,C39) -> Phân tích nguyên sơ của idean | D40: Phạm Cẩm Vân | E40: 3110122102 | F40: 22ST2 | I40: KHOA TOÁN (14 đề tài) | J40: =IFS( ISNUMBER(SEARCH("toán",I40)),"Khoa Toán - Tin, Trường ĐHSP", ISNUMBER(SEARCH("tin",I40)),"Khoa Toán - Tin, Trường ĐHSP", ISNUMBER(SEARCH("lý",I40)),"Khoa Lý - Hóa, Trường ĐHSP", ISNUMBER(SEARCH("hóa",I40)),"Khoa Lý - Hóa, Trường ĐHSP", ISNUMBER(SEARCH("ngữ văn",I40)),"Khoa Ngữ văn - Truyền thông, Trường ĐHSP", ISNUMBER(SEARCH("sử",I40)),"Khoa Sử - Địa - Chính trị, Trường ĐHSP", ISNUMBER(SEARCH("địa",I40)),"Khoa Sử - Địa - Chính trị, Trường ĐHSP", ISNUMBER(SEARCH("chính trị",I40)),"Khoa Sử - Địa - Chính trị, Trường ĐHSP", ISNUMBER(SEARCH("sinh",I40)),"Khoa Sinh - Nông nghiệp - Môi trường, Trường ĐHSP", ISNUMBER(SEARCH("tiểu học",I40)),"Khoa Giáo dục Tiểu học - Mầm non, Trường ĐHSP", ISNUMBER(SEARCH("mầm non",I40)),"Khoa Giáo dục Tiểu học - Mầm non, Trường ĐHSP", ISNUMBER(SEARCH("nghệ thuật",I40)),"Khoa Giáo dục Nghệ thuật - Thể chất, Trường ĐHSP", ISNUMBER(SEARCH("tâm lý",I40)),"Khoa Tâm lý - Giáo dục - Công tác Xã hội, Trường ĐHSP" ) -> #NAME? | K40: =VLOOKUP(J40,'Bảng Đơn vị'!$A$2:$B$10,2,1) -> #NAME? | L40: 45705 | M40: 2025
...

Sheet BangLHS_2025_2026
A1: STT | B1: Năm | C1: Khóa/ Lớp | D1: Họ và tên | E1: Ngày sinh | F1: Giới tính | G1: Quốc tịch | H1: Trường chủ quản ở nước ngoài (đối với LHS trao đổi/ thực tập) | I1: Ngành học tại đơn vị | J1: Ngành học | K1: donvi_ma | L1: donvi_ten | M1: Diện | N1: Số hộ chiếu | O1: Địa chỉ tạm trú | P1: Số visa/Thẻ tạm trú | Q1: Ngày nhập cảnh | R1: Thời hạn tạm trú | S1: Ghi chú
A2: 1 | B2: 2022 | C2: 2022 | D2: CHANTHAVISOUK SATSAMAY | E2: 30756 | F2: Nam | G2: Lào | I2: Nghiên cứu sinh ngành Hệ thống thông tin | J2: Hệ thống thông tin | K2: D2504200 | L2: Khoa Toán - Tin, Trường ĐHSP | M2: Học bổng TPTT 100% | N2: P 607808 | O2: 459 Tôn Đức Thắng, Liên Chiểu | S2: Đang ở Lào
A3: 2 | B3: 2022 | C3: 2022 | D3: Teh Jia Rou | E3: 35105 | F3: Nữ | G3: Malaysia | I3: Nghiên cứu sinh ngành Lịch sử Việt Nam | J3: Lịch sử Việt Nam | K3: D2504270 | L3: Khoa Sử - Địa - Chính trị, Trường ĐHSP | M3: Tự túc | N3: A54965993 | O3: 123 Nguyễn Xuân Hữu, quận Cẩm Lệ, thành phố Đà Nẵng | P3: AI 1462691 | Q3: 45397 | R3: 45761
A4: 3 | B4: 2021 | C4: 2021 | D4: Liu Li Xian | E4: 32672 | F4: Nữ | G4: Trung Quốc | I4: Nghiên cứu sinh ngành Ngôn ngữ học | J4: Ngôn ngữ học | K4: D2504240 | L4: Khoa Ngữ văn - Truyền thông, Trường ĐHSP | M4: Học bổng ĐHSP | N4: EJ2448338 | O4: 459 Tôn Đức Thắng, Liên Chiểu
A5: 4 | B5: 2021 | C5: 2021 | D5: Zhang Qiuxia | E5: 34184 | F5: Nữ | G5: Trung Quốc | I5: Nghiên cứu sinh ngành Ngôn ngữ học | J5: Ngôn ngữ học | K5: D2504240 | L5: Khoa Ngữ văn - Truyền thông, Trường ĐHSP | M5: Học bổng ĐHSP | N5: EI4285958 | O5: 459 Tôn Đức Thắng, Liên Chiểu | S5: chưa nhập cảnh
A6: 5 | B6: 2021 | C6: 2021 | D6: Lonphanh Phaodavanh | E6: 25065 | F6: Nam | G6: Lào | I6: Nghiên cứu sinh ngành Quản lí giáo dục | J6: Quản lý giáo dục | K6: D2504260 | L6: Khoa Tâm lý - Giáo dục - Công tác Xã hội, Trường ĐHSP | M6: Học bổng Hiệp Định | N6: D 0037583 | O6: Tổng LSQ Lào tại Thành phố Hồ Chí Minh | R6: 45912 | S6: Chứng minh thư lãnh sự số 172/LS-HCM/2022
A7: 6 | B7: 2022 | C7: 2022 | D7: Umvong Kiengcay | E7: 14/12/1986 | F7: Nam | G7: Lào | I7: Nghiên cứu sinh ngành Quản lí Giáo dục | J7: Quản lý giáo dục | K7: D2504260 | L7: Khoa Tâm lý - Giáo dục - Công tác Xã hội, Trường ĐHSP | M7: Học bổng TPTT 100% | N7: PA 0249189 | O7: 459 Tôn Đức Thắng, Liên Chiểu | S7: Miễn thị thực 28 ngày
A8: 7 | B8: 2024 | C8: 2024 | D8: XAYAVONG SOMPHONE | E8: 31170 | F8: Nam | G8: Lào | I8: Nghiên cứu sinh ngành Quản lí Giáo dục | J8: Quản lý giáo dục | K8: D2504260 | L8: Khoa Tâm lý - Giáo dục - Công tác Xã hội, Trường ĐHSP | M8: Học bổng TPTT 100% | N8: PA 0445175 | O8: 459 Tôn Đức Thắng, Liên Chiểu | S8: Miễn thị thực 28 ngày
A9: 8 | B9: 2024 | C9: 2024 | D9: Baolopet Songpon | E9: 26/01/1981 | F9: Nam | G9: Thái Lan | I9: Nghiên cứu sinh ngành Ngôn ngữ học | J9: Ngôn ngữ học | K9: D2504240 | L9: Khoa Ngữ văn - Truyền thông, Trường ĐHSP | M9: học bổng Trường ĐHSP | N9: OF2019890 | S9: Chưa nhập cảnh
A10: 9 | B10: 2025 | C10: 2025 | D10: DENG YANJIAO | E10: 19/9/1992 | F10: Nữ | G10: Trung Quốc | I10: Nghiên cứu sinh ngành Lịch sử Việt Nam | J10: Lịch sử Việt Nam | K10: D2504270 | L10: Khoa Sử - Địa - Chính trị, Trường ĐHSP | N10: EJ7562017 | O10: 459 Tôn Đức Thắng, Liên Chiểu
A11: 10 | B11: 2023 | C11: 2023/K47 | D11: ANONGSACK SOUKSAVATH | E11: 28976 | F11: Nam | G11: Lào | I11: Quản lý giáo dục | J11: Quản lý giáo dục | K11: D2504260 | L11: Khoa Tâm lý - Giáo dục - Công tác Xã hội, Trường ĐHSP | M11: K47 TPTT 100% CV 8798/UBND-SNG ngày 29/12/2021 | N11: P2372620 | O11: 459 Tôn Đức Thắng, Liên Chiểu | P11: AI 2301642 | Q11: 45041 | R11: 02/4/2025
A12: 11 | B12: 2023 | C12: 2023/K47 | D12: XAYSONGKHAM KHAMPHONG | E12: 31547 | F12: Nam | G12: Lào | I12: Quản lý giáo dục | J12: Quản lý giáo dục | K12: D2504260 | L12: Khoa Tâm lý - Giáo dục - Công tác Xã hội, Trường ĐHSP | M12: K47 TPTT 100% CV 8798/UBND-SNG ngày 29/12/2021 | N12: PA0369628 | O12: 459 Tôn Đức Thắng, Liên Chiểu | P12: AI 2301643 | Q12: 45041 | R12: 02/4/2025
A13: 12 | B13: 2023 | C13: 2023/K47 | D13: PASANPHONE PHONEPASEUTH | E13: 30726 | F13: Nữ | G13: Lào | I13: Quản lý giáo dục | J13: Quản lý giáo dục | K13: D2504260 | L13: Khoa Tâm lý - Giáo dục - Công tác Xã hội, Trường ĐHSP | M13: K47 TPTT 100% CV 8797/UBND-SNG ngày 29/12/2021 | N13: P2376255 | O13: 459 Tôn Đức Thắng, Liên Chiểu | P13: AI1760826 | Q13: 45041 | S13: Miễn thị thực 28 ngày
A14: 13 | B14: 2023 | C14: 2023/K47 | D14: THONGSI KHAMMAI | E14: 31171 | F14: Nữ | G14: Lào | I14: Quản lý giáo dục | J14: Quản lý giáo dục | K14: D2504260 | L14: Khoa Tâm lý - Giáo dục - Công tác Xã hội, Trường ĐHSP | M14: K47 TPTT 100% CV 8795/UBND-SNG ngày 29/12/2021 | N14: P2376845 | O14: 459 Tôn Đức Thắng, Liên Chiểu | P14: AI1760825 | Q14: 45041 | S14: Miễn thị thực 28 ngày
A15: 14 | B15: 2023 | C15: 2023/K47 | D15: PHOMCHANTHA DONE | E15: 33425 | F15: Nam | G15: Lào | I15: Lý luận và Phương pháp dạy học bộ môn Vật lý | J15: Lý luận và Phương pháp dạy học bộ môn Vật lý | K15: D2504210 | L15: Khoa Lý - Hóa, Trường ĐHSP | M15: K47 100 % Công văn số 8798/UBND-SNG ngày 29/12/2021 | N15: P2377600 | O15: 459 Tôn Đức Thắng, Liên Chiểu | P15: AI1760820 | Q15: 45041 | S15: Miễn thị thực 28 ngày
A16: 15 | B16: 2023 | C16: 2023/K47 | D16: ONCHANXAI KEONALIN | E16: 30359 | F16: Nam | G16: Lào | I16: Quản lý giáo dục | J16: Quản lý giáo dục | K16: D2504260 | L16: Khoa Tâm lý - Giáo dục - Công tác Xã hội, Trường ĐHSP | M16: K47 100 % Công văn số 8795/UBND-SNG ngày 29/11/2021 | N16: P2377160 | O16: 459 Tôn Đức Thắng, Liên Chiểu | P16: AI 2301646 | Q16: 45041 | S16: Miễn thị thực 28 ngày
A17: 16 | B17: 2023 | C17: 2023/K47 | D17: MANHMANYSAY VONGSACK | E17: 31242 | F17: Nam | G17: Lào | I17: Phương pháp toán sơ cấp | J17: Phương pháp toán sơ cấp | K17: D2504200 | L17: Khoa Toán - Tin, Trường ĐHSP | M17: K47 100 % Công văn số 8798/UBND-SNG ngày 29/12/2021 | N17: P2377160 | O17: 459 Tôn Đức Thắng, Liên Chiểu | P17: AI1760822 | Q17: 45041 | R17: 02/4/2025
A18: 17 | B18: 2023 | C18: 2023/K47 | D18: XAYAPHONE NOUNKHAM | E18: 31174 | F18: Nam | G18: Lào | I18: Quản lý giáo dục | J18: Quản lý giáo dục | K18: D2504260 | L18: Khoa Tâm lý - Giáo dục - Công tác Xã hội, Trường ĐHSP | M18: K47 100% Công văn số 7049/UBND-SNG ngày 22/12/2022 | N18: P2075488 | O18: Ký túc xá Trường Đại học Sư phạm | S18: Miễn thị thực 28 ngày
A19: 18 | B19: 2023 | C19: 2023/K47 | D19: VILAISACK NANTAVATH | E19: 31143 | F19: Nam | G19: Lào | I19: Lý luận và Phương pháp dạy học bộ môn Địa lý | J19: Lý luận và Phương pháp dạy học bộ môn Địa lý | K19: D2504270 | L19: Khoa Sử - Địa - Chính trị, Trường ĐHSP | M19: K47 100% Công văn số 7044/UBND-SNG ngày 22/12/2022 | N19: PA0472659 | O19: Ký túc xá Trường Đại học Sư phạm | P19: AI2301089 | Q19: 45226 | R19: 45635
A20: 19 | B20: 2023 | C20: 2023/K47 | D20: SAITHONGDUANG OUDOMXAY | E20: 33843 | F20: Nam | G20: Lào | I20: Toán Giải tích | J20: Toán Giải tích | K20: D2504200 | L20: Khoa Toán - Tin, Trường ĐHSP | M20: K47 100% Công văn số 7050/UBND-SNG ngày 22/12/2022 | N20: PA0236772 | O20: Ký túc xá Trường Đại học Sư phạm | P20: AI 2301090 | Q20: 45220 | R20: 45635
A21: 20 | B21: 2023 | C21: 2023/K47 | D21: Sisoulath Somsack | E21: 32332 | F21: Nam | G21: Lào | I21: Lịch sử Việt Nam | J21: Lịch sử Việt Nam | K21: D2504270 | L21: Khoa Sử - Địa - Chính trị, Trường ĐHSP | M21: K47 100% Công văn số 7049/UBND-SNG ngày 22/12/2022 | N21: PA0273394 | O21: Ký túc xá Trường Đại học Sư phạm | S21: Miễn thị thực 28 ngày
A22: 21 | B22: 2023 | C22: 2023/K48 | D22: Keosomvang Tadam | E22: 10/06/1991 | F22: Nữ | G22: Lào | I22: Giáo dục học | J22: Giáo dục học | K22: D2504260 | L22: Khoa Tâm lý - Giáo dục - Công tác Xã hội, Trường ĐHSP | M22: K48 100% Công văn số 6041/UBND-SNG ngày 02/11/2023 | N22: P2056368 | O22: Ký túc xá Trường Đại học Sư phạm | S22: Miễn thị thực 28 ngày
A23: 22 | B23: 2023 | C23: 2023/K48 | D23: Mommabath Beng | E23: 06/01/1995 | F23: Nam | G23: Lào | I23: Hóa hữu cơ | J23: Hóa hữu cơ | K23: #N/A | L23: #N/A | M23: K48 100% Công văn số 6043/UBND-SNG ngày 02/11/2023 | N23: P2740079 | O23: Ký túc xá Trường Đại học Sư phạm | P23: AI 2302849 | Q23: 18/4/25 | R23: 11/5/2026 | S23: Gia hạn lúc tháng 5/2025
A24: 23 | B24: 2023 | C24: 2023/K48 | D24: Saysongkham Latdavanh | E24: 15/06/1987 | F24: Nữ | G24: Lào | I24: Lịch sử Việt Nam | J24: Lịch sử Việt Nam | K24: D2504270 | L24: Khoa Sử - Địa - Chính trị, Trường ĐHSP | M24: K48 100% Công văn số 6043/UBND-SNG ngày 02/11/2023 | N24: P2439512 | O24: Ký túc xá Trường Đại học Sư phạm | S24: Miễn thị thực 28 ngày
A25: 24 | B25: 2023 | C25: 2023/K48 | D25: Kongmanivong Bounyong | E25: 26/6/1983 | F25: Nam | G25: Lào | I25: Quản lý giáo dục | J25: Quản lý giáo dục | K25: D2504260 | L25: Khoa Tâm lý - Giáo dục - Công tác Xã hội, Trường ĐHSP | M25: K48 100% Công văn số 7044/UBND-SNG ngày 22/12/2022 | N25: P2426969 | O25: Ký túc xá Trường Đại học Sư phạm | S25: Miễn thị thực 28 ngày
A26: 25 | B26: 2023 | C26: 2023/K48 | D26: Khoonboudpounminur Daosadeth | E26: 13/12/1983 | F26: Nam | G26: Lào | I26: Quản lý giáo dục | J26: Quản lý giáo dục | K26: D2504260 | L26: Khoa Tâm lý - Giáo dục - Công tác Xã hội, Trường ĐHSP | M26: K48 100% Công văn số 7049/UBND-SNG ngày 22/12/2022 | N26: P2464425 | O26: Ký túc xá Trường Đại học Sư phạm | S26: Miễn thị thực 28 ngày
A27: 26 | B27: 2023 | C27: 2023/K48 | D27: Phiewkhamphanh Phoudthasone | E27: 07/12/1995 | F27: Nữ | G27: Lào | I27: Quản lý giáo dục | J27: Quản lý giáo dục | K27: D2504260 | L27: Khoa Tâm lý - Giáo dục - Công tác Xã hội, Trường ĐHSP | M27: K48 50% Công văn số 7050/UBND-SNG ngày 22/12/2022 | N27: P24633665 | O27: Ký túc xá Trường Đại học Sư phạm | S27: Miễn thị thực 28 ngày
A28: 27 | B28: 2023 | C28: 2023/K48 | D28: Vongsa Phoumsavanh | E28: 09/03/1988 | F28: Nam | G28: Lào | I28: Quản lý giáo dục | J28: Quản lý giáo dục | K28: D2504260 | L28: Khoa Tâm lý - Giáo dục - Công tác Xã hội, Trường ĐHSP | M28: K48 100% Công văn số 7045/UBND-SNG ngày 22/12/2022 | N28: PA0470333 | O28: Ký túc xá Trường Đại học Sư phạm | P28: AI 2302881 | Q28: 17/4/2025 | R28: 22/5/2026 | S28: Gia hạn lúc tháng 6/2025
A29: 28 | B29: 2023 | C29: 2023/K48 | D29: Douangchantha Sisamay | E29: 24/11/1980 | F29: Nam | G29: Lào | I29: Quản lý giáo dục | J29: Quản lý giáo dục | K29: D2504260 | L29: Khoa Tâm lý - Giáo dục - Công tác Xã hội, Trường ĐHSP | M29: K48 100% Công văn số 7050/UBND-SNG ngày 22/12/2022 | N29: P1587935 | O29: Ký túc xá Trường Đại học Sư phạm | S29: Miễn thị thực 28 ngày
A30: 29 | B30: 2023 | C30: 2023/K48 | D30: Khanthachak Soulivong | E30: 03/06/1990 | F30: Nam | G30: Lào | I30: Quản lý giáo dục | J30: Quản lý giáo dục | K30: D2504260 | L30: Khoa Tâm lý - Giáo dục - Công tác Xã hội, Trường ĐHSP | M30: K48 50% Công văn số 7044/UBND-SNG ngày 22/12/2022 | N30: PA0479515 | O30: Ký túc xá Trường Đại học Sư phạm | P30: AI 2302878 | Q30: 18/4/2025 | R30: 22/5/2026 | S30: Gia hạn lúc tháng 6/2025
